お疲れ様です。現在、app.pyを実行した際に以下のエラーが発生しています：
(venv) root@vm-b3dba883-74:~/M-S-A# python app.py
  File "/root/M-S-A/app.py", line 1377
    @app.route('/api/hourly-analysis')
SyntaxError: expected 'except' or 'finally' block

このエラーは、行1377付近（@app.route('/api/hourly-analysis')）で構文エラーが発生していることを示しています。具体的には、Pythonがtryブロックに対応するexceptまたはfinallyブロックを期待しているのに、それが見つからないことが原因です。
問題の原因
コードを確認したところ、api_genre_ranking()関数の定義内で、tryブロックが開始されていますが、対応するexceptまたはfinallyブロックが閉じられていないまま、次の関数定義（api_hourly_analysis()）が始まっていることが原因と考えられます。以下のように、tryブロックの終了が不完全な状態で次のデコレーターが記述されている可能性があります：
python
            return jsonify({...})
        # ここで try ブロックが閉じられていない
# 次の関数定義が直後に始まっている
@app.route('/api/hourly-analysis')
@cache.memoize(timeout=600)
def api_hourly_analysis():

修正方法
以下の手順でコードを修正してください：
api_genre_ranking()関数の確認と修正
app.pyのapi_genre_ranking()関数（/api/ranking/genreエンドポイント）の最後を確認してください。

最後のreturn jsonify({...})の後で、tryブロックが適切に閉じられていない場合、exceptブロックが不足しています。

以下のように、対応するexceptブロックを追加して、tryを正しく閉じてください：
python
@app.route('/api/ranking/genre')
@cache.memoize(timeout=600)
def api_genre_ranking():
    biz_type = request.args.get('biz_type')
    jst = pytz.timezone('Asia/Tokyo')
    now_jst = datetime.now(jst)

    if not biz_type:
        app.logger.info("業種が指定されていません。全業種のジャンルランキングを返します。")
        try:
            conn = get_db_connection()
            query = """
            SELECT 
                genre,
                COUNT(DISTINCT store_name) as store_count,
                AVG((working_staff - active_staff) * 100.0 / working_staff) as avg_rate
            FROM store_status
            WHERE working_staff > 0 AND genre IS NOT NULL AND genre != ''
            GROUP BY genre
            ORDER BY avg_rate DESC
            """
            cursor = conn.execute(query)
            results = cursor.fetchall()
            conn.close()
            # ... (中略) ...
            return jsonify({
                "data": data,
                "meta": {
                    "biz_type": "全業種",
                    "count": len(data),
                    "current_time": now_jst.strftime('%Y-%m-%d %H:%M:%S %Z%z')
                }
            }), 200
        except Exception as e:  # 不足していた except ブロックを追加
            app.logger.error(f"全業種ジャンルランキング取得エラー: {e}")
            app.logger.error(traceback.format_exc())
            return jsonify({
                "data": [
                    {"genre": "データ取得エラー", "store_count": 0, "avg_rate": 0.0}
                ],
                "meta": {
                    "error": str(e),
                    "message": "全業種ジャンルランキングの取得中にエラーが発生しました",
                    "current_time": now_jst.strftime('%Y-%m-%d %H:%M:%S %Z%z')
                }
            }), 200

    try:
        # ... (中略) ...
        return jsonify({
            "data": data,
            "meta": {
                "biz_type": biz_type,
                "count": len(data),
                "current_time": now_jst.strftime('%Y-%m-%d %H:%M:%S %Z%z')
            }
        }), 200
    except Exception as query_error:  # この except ブロックは既にあるが、確認を
        if conn:
            conn.close()
        app.logger.error(f"ジャンルランキングクエリエラー: {query_error}")
        app.logger.error(traceback.format_exc())
        return jsonify({
            "data": [
                {"genre": "エラー発生", "store_count": 0, "avg_rate": 0.0}
            ],
            "meta": {
                "error": str(query_error),
                "message": "ジャンルランキングクエリの実行中にエラーが発生しました",
                "biz_type": biz_type,
                "current_time": now_jst.strftime('%Y-%m-%d %H:%M:%S %Z%z')
            }
        }), 200  # ここで try-except を正しく閉じる
上記の例では、既存のtryブロックに不足していたexceptを追加し、さらに外側のtryブロックにも正しい終了を保証しています。
構文の全体確認
api_genre_ranking()関数の直後にapi_hourly_analysis()が定義されていますが、間の構文が途切れていないか確認してください。

もしtryのインデントが不正で、次の関数定義がtryブロック内に誤って含まれている場合、正しいインデントに修正してください。
修正後の動作確認
修正後、再度python app.pyを実行し、エラーが解消されるか確認してください。

エラーが解消されない場合、修正したコード全体と新しいエラーメッセージを共有してください。
補足
エラーメッセージにある「line 1377」は、提供されたコードの行数と一致しない可能性があります。実際のファイルでの行数を確認し、@app.route('/api/hourly-analysis')付近のコードを重点的にチェックしてください。

もし他に未閉じのtryブロックがある場合も、同様にexceptまたはfinallyで閉じる必要があります。
お手数ですが、上記の指示に基づいて修正をお願いします。何か不明点があれば、遠慮なく質問してください！
